Workbook

Sheet Requirement list
B2: ETHDC Technologies Pvt. Ltd
B3: Statutory Audit for the year ended March 31, 2026
B4: Preliminary Requirement list
B7: Sr No | C7: Document / Information requirements | D7: Status | E7: Remarks
B8: 1 | C8: Trial Balance FY 2025-26
B10: =B8+1 -> 2 | C10: Secretarial compliances: 2025-26
C11: General Meetings
C12: Board Meetings
C13: All the registers to be prepared under Companies act,2013
C14: Forms - year end | E14: Refer Annexure 1
C15: Secretarial compliance certificate
B17: =B10+1 -> 3 | C17: Copy of Payment challans and returns 2025-26 (monthly or quarterly, as the case may be)
C18: - Profession tax
C19: - Provident Fund / ESI
C20: - ESIC
C21: - TDS / TCS
C22: 192B
C23: 194 C
C24: 194 J
C25: 194 I
C26: - TDS on foreign payment (If any)
C27: - GST credentials
C28: - GST returns summary (3B and GSTR1)
C29: - Electronic cash and Credit ledger
... C31: - Reco of GST ECL closing Balance vs Books
B33: =B17+1 -> 4 | C33: Status of year wise assessments under all the above acts, whether any demand pending in appeal from any of the concerned department. Also status of any ongoing legal claims. This needs to be in the form of management representation letter.
B35: =B33+1 -> 5 | C35: Sundry creditors -
C36: Balance confirmation of top 5 creditors as on March 31, 2026
C37: List of creditors registered under MSMED Act, 2006
B39: =B35+1 -> 6 | C39: List of Accrued liability and Provisions
B41: =B39+1 -> 7 | C41: Details of any Contingent Liabilities
B43: =B41+1 -> 8 | C43: Fixed asset register
C44: - Updated FAR as on March 31, 2026 with depreciation working as per Companies Act
C45: - Updated FAR as on March 31, 2026 with depreciation working as per Income tax act
C46: - Asset addition verfication - Invoices
C47: - Working of loss/profit on sale of fixed assets
B49: =B43+1 -> 9 | C49: Sundry debtors
C50: Balance confirmation of top 5 debtors as on March 31, 2026
B52: =B49+1 -> 10 | C52: Cash certificate for cash as on March 31, 2026 signed by cashier and verified by Accounts Manager
B54: =B52+1 -> 11 | C54: Bank balance confirmation as on March 31, 2026 and reconciliation items if any
...

Sheet Annexure 1
B2: ='Requirement list'!B2 -> ETHDC Technologies Pvt. Ltd
B3: ='Requirement list'!B3 -> Statutory Audit for the year ended March 31, 2026
B4: Secretarial Documents
B7: Secretarial documents
B8: DIR 8
B9: MBP 1
B10: MSME return
B11: AOC 4 of FY 2024-25 (Annual return)
B12: DPT- 3
B13: Shareholding pattern
B14: Minutes of meetings

Sheet Annexure 2 sales sample
B2: ='Requirement list'!B2 -> ETHDC Technologies Pvt. Ltd
B3: ='Requirement list'!B3 -> Statutory Audit for the year ended March 31, 2026
B4: ='Requirement list'!B4 -> Preliminary Requirement list
B6: Annexure 2
B8: Sales invoices samples list | J8: Contracts with parties
B10: Date | C10: Party name | D10: Invoice no. | E10: Debit | F10: Credit | G10: Status | J10: Sr. no. | K10: Party name | L10: Status
B11: 45385 | C11: Indian School Muscat | D11: ETHDC23E671 | F11: 693541.4 | G11: Received | J11: 1 | K11: Private International English School | L11: No agreement - on invoice basis
B12: 45415 | C12: St. Mary's Private High School LLC | D12: ETHDC23PE116 | F12: 152213.4 | J12: 2 | K12: Ganatra International LLC | L12: Received
B13: 45457 | C13: NorthStar Technology Company WLL | D13: ETHDC23E698 | F13: 920483.37 | G13: Received | J13: 3 | K13: Edison Group of Schools | L13: Received
B14: 45489 | C14: DC Netra Technologies - Sole Proprietorship LLC | D14: ETHDC23E711 | F14: 1024030.6 | G14: Received | J14: 4 | K14: SKP'S CM International School
B15: 45506 | C15: Indian School Bahrain | D15: ETHDC23E720 | F15: 441679.63 | G15: Received | J15: 5 | K15: DC Netra Technologies - Sole Proprietorship LLC
B16: 45533 | C16: Capital School | D16: ETHDC23E731 | F16: 258904.72 | G16: Received | J16: 6 | K16: Al Khaleejia Business Management Company | L16: Received
B17: 45538 | C17: Seven Eleven Education Society | D17: ETHDC23D1476 | F17: 96000 | G17: Received | J17: 7 | K17: Edison International Academy - Aspire | L17: single agreement for entire group
B18: 45540 | C18: Doha International School | D18: ETHDC23E747 | F18: 230893.56 | G18: Received
B19: 45572 | C19: Middle East International School | D19: ETHDC23E764 | F19: 217640.32 | G19: Received
B20: 45572 | C20: Prudentz Corp IT Solutions LLC | D20: ETHDC23E757 | F20: 287753.75 | G20: Received
B21: 45600 | C21: St. Mary's Catholic High School (British Curriculum) | D21: ETHDC23E766 | F21: 248060.16 | G21: Received
B22: 45602 | C22: Edison Group of Schools | D22: ETHDC23E773 | F22: 260428.73 | G22: Received
B23: 45625 | C23: Al Khaleejia Business Management Company | D23: ETHDC23E780 | F23: 1450385.2 | G23: Received
B24: 45653 | C24: DC Netra Technologies - Sole Proprietorship LLC | D24: ETHDC23E785 | F24: 744584.32 | G24: Received
B25: 45656 | C25: Alia National School | D25: ETHDC23E792 | F25: 409594.93 | G25: Received
B26: 45660 | C26: NorthStar Technology Company WLL | D26: ETHDC23E796 | F26: 1756141.9 | G26: Received
B27: 45666 | C27: Bu Oauf Trading - ARKIS | D27: ETHDC23PE155 | F27: 421700.48
B28: 45691 | C28: The Asian School | D28: ETHDC23E902 | F28: 455892.41 | G28: Received
B29: 45691 | C29: Hawar International School | D29: ETHDC23E901 | F29: 890357.88 | G29: Received
B30: 45728 | C30: Ganatra International LLC | D30: ETHDC23E929 | F30: 603037.86 | G30: Received
B31: 45741 | C31: Fresh & Honest Cafe Limited | D31: ETHDC23D1678 | F31: 500000 | G31: Received

Sheet Annexure 3 samples
B2: ='Requirement list'!B2 -> ETHDC Technologies Pvt. Ltd
B3: ='Requirement list'!B3 -> Statutory Audit for the year ended March 31, 2026
B4: ='Requirement list'!B4 -> Preliminary Requirement list
B6: Annexure 3
B8: Expenses Samples List
B10: 1. Professional fees
B12: Date | C12: account_name | D12: transaction_details | E12: transaction_id | F12: reference_transaction_id | G12: offset_account_id | H12: offset_account_type | I12: transaction_type | J12: reference_number | K12: entity_number | L12: debit | M12: credit | N12: net_amount | O12: contact_id | P12: account_id | Q12: project_ids | R12: description | S12: currency_code | T12: account_group | U12: account_type | V12: branch_name
B13: 45453 | C13: Professional Fees | D13: Genius Consultants | E13: 1275371000001303027 | I13: bill | K13: GM2PPR/JU0008/25 | L13: 4830 | N13: 4830 | O13: 1275371000000086189 | P13: 1275371000000112001 | S13: INR | T13: expense | U13: expense | V13: Head Office | W13: Received
B14: 45565 | C14: Professional Fees | D14: Vaishnavi kulkarni | E14: 1275371000001425523 | I14: bill | K14: VSK01 | L14: 180000 | N14: 180000 | O14: 1275371000000147197 | P14: 1275371000000112001 | S14: INR | T14: expense | U14: expense | V14: Head Office | W14: Received
B15: 45626 | C15: Professional Fees | D15: Aditi Raibagkar | E15: 1275371000001429430 | I15: bill | K15: #11 | L15: 17500 | N15: 17500 | O15: 1275371000001429416 | P15: 1275371000000112001 | S15: INR | T15: expense | U15: expense | V15: Head Office | W15: Received
B16: 45741 | C16: Professional Fees | D16: Vaibhav Patil | E16: 1275371000001663730 | I16: bill | K16: VP/24-25 | L16: 81830 | N16: 81830 | O16: 1275371000001663414 | P16: 1275371000000112001 | S16: INR | T16: expense | U16: expense | V16: Head Office | W16: Received
B17: 45742 | C17: Professional Fees | D17: Sagar Dani | E17: 1275371000001663562 | I17: bill | K17: ETHDC24-25 | L17: 328548 | N17: 328548 | O17: 1275371000001663386 | P17: 1275371000000112001 | S17: INR | T17: expense | U17: expense | V17: Head Office | W17: Received
B20: 2. Serve charges
B22: Contract with : ESDS SOFTWARE SOLUTION LIMITED
B24: Date | C24: account_name | D24: transaction_details | E24: transaction_id | F24: reference_transaction_id | G24: offset_account_id | H24: offset_account_type | I24: transaction_type | J24: reference_number | K24: entity_number | L24: debit | M24: credit | N24: net_amount | O24: contact_id | P24: account_id | Q24: project_ids | R24: description | S24: currency_code | T24: account_group | U24: account_type | V24: branch_name
B25: 45444 | C25: Server Charges | D25: Hostnet India | E25: 1275371000001079713 | I25: bill | K25: 13248 | L25: 13600 | N25: 13600 | O25: 1275371000000303647 | P25: 1275371000000112103 | S25: INR | T25: expense | U25: expense | V25: Head Office | W25: Received
B26: 45576 | C26: Server Charges | D26: ESDS SOFTWARE SOLUTION LIMITED | E26: 1275371000001424473 | I26: bill | K26: HOST-2425-1819 | L26: 447680 | N26: 447680 | O26: 1275371000000112109 | P26: 1275371000000112103 | S26: INR | T26: expense | U26: expense | V26: Head Office | W26: Received
B27: 45660 | C27: Domain & Web Hosting Exp | D27: PODC | E27: 1275371000001663105 | I27: bill | K27: 432/24-25 | L27: 146220 | N27: 146220 | O27: 1275371000000124124 | P27: 1275371000000124151 | S27: INR | T27: expense | U27: other_expense | V27: Head Office | W27: Received
B29: 3. Software expenses
B31: Date | C31: account_name | D31: transaction_details | E31: transaction_id | F31: reference_transaction_id | G31: offset_account_id | H31: offset_account_type | I31: transaction_type | J31: reference_number | K31: entity_number | L31: debit | M31: credit | N31: net_amount | O31: contact_id | P31: account_id | Q31: project_ids | R31: description | S31: currency_code | T31: account_group | U31: account_type | V31: branch_name
B32: 45446 | C32: Software & Tools | D32: MP, SK Muscat Hotel | E32: 1275371000001670449 | I32: journal | K32: 451 | L32: 15505.36 | N32: 15505.36 | O32: -1 | P32: 1275371000000442368 | S32: INR | T32: expense | U32: expense | V32: Head Office | W32: Received
B33: 45490 | C33: Software & Tools | D33: Google Ads | E33: 1275371000001673181 | I33: journal | K33: 469 | L33: 32500 | N33: 32500 | O33: -1 | P33: 1275371000000442368 | S33: INR | T33: expense | U33: expense | V33: Head Office | W33: Received
B34: 45657 | C34: Software & Tools | D34: ICICI Bank | E34: 1275371000001685847 | G34: 1275371000000046001 | H34: bank | I34: expense | L34: 11776.4 | N34: 11776.4 | O34: -1 | P34: 1275371000000442368 | R34: Bitrix payment to anjali for nov and dec | S34: INR | T34: expense | U34: expense | V34: Head Office | W34: Received
B37: 4. Travelling and Conveyance
B39: Date | C39: account_name | D39: transaction_details | E39: transaction_id | F39: reference_transaction_id | G39: offset_account_id | H39: offset_account_type | I39: transaction_type | J39: reference_number | K39: entity_number | L39: debit | M39: credit | N39: net_amount | O39: contact_id | P39: account_id | Q39: project_ids | R39: description | S39: currency_code | T39: account_group | U39: account_type | V39: branch_name
B40: 45400 | C40: International Travelling Exp | D40: CC 1021 (Qatar travel) | E40: 1275371000001670141 | I40: journal | K40: 436 | L40: 134866.05 | N40: 134866.05 | O40: -1 | P40: 1275371000000123627 | S40: INR | T40: expense | U40: other_expense | V40: Head Office | W40: Received
B41: 45435 | C41: International Travelling Exp | D41: Hrishikesh BH (99012.56) | E41: 1275371000001670369 | I41: journal | K41: 447 | L41: 108237 | N41: 108237 | O41: -1 | P41: 1275371000000123627 | S41: INR | T41: expense | U41: other_expense | V41: Head Office | W41: Received
B42: 45673 | C42: International Travelling Exp | D42: Pheroze | E42: 1275371000001494173 | I42: bill | K42: #Jan | L42: 176117 | N42: 176117 | O42: 1275371000000123993 | P42: 1275371000000123627 | R42: Sagar, Nilesh, AK | S42: INR | T42: expense | U42: other_expense | V42: Head Office | W42: Received
B43: 45576 | C43: Travelling agent commission | D43: Garuda Gateways | E43: 1275371000001528483 | I43: bill | K43: ITI240000145 | L43: 5000 | N43: 5000 | O43: 1275371000000086232 | P43: 1275371000000301503 | S43: INR | T43: expense | U43: other_expense | V43: Head Office
B44: 45454 | C44: Domestic Travelling | D44: cab | E44: 1275371000001670529 | I44: journal | K44: 455 | L44: 5000 | N44: 5000 | O44: -1 | P44: 1275371000000123597 | S44: INR | T44: expense | U44: other_expense | V44: Head Office
B45: 45453 | C45: Domestic Travelling | D45: omerga visit | E45: 1275371000001796387 | I45: journal | K45: 561 | L45: 23659 | N45: 23659 | O45: -1 | P45: 1275371000000123597 | S45: INR | T45: expense | U45: other_expense | V45: Head Office | W45: Received
B46: 45543 | C46: Local Conveyance | D46: sandesh auti | E46: 1275371000001796707 | I46: journal | K46: 577 | L46: 3905 | N46: 3905 | O46: -1 | P46: 1275371000000169187 | S46: INR | T46: expense | U46: other_expense | V46: Head Office | W46: Received
B47: 45553 | C47: Travel Expense | D47: ICICI Bank | E47: 1275371000002087847 | G47: 1275371000000046001 | H47: bank | I47: expense | L47: 25768 | N47: 25768 | O47: -1 | P47: 1275371000000000516 | R47: Harichandra darekar exp to e booked now booked under travel ex | S47: INR | T47: expense | U47: expense | V47: Head Office
B50: 5. Office Expense
B52: Date | C52: account_name | D52: transaction_details | E52: transaction_id | F52: reference_transaction_id | G52: offset_account_id | H52: offset_account_type | I52: transaction_type | J52: reference_number | K52: entity_number | L52: debit | M52: credit | N52: net_amount | O52: contact_id | P52: account_id | Q52: project_ids | R52: description | S52: currency_code | T52: account_group | U52: account_type | V52: branch_name
B53: 45547 | C53: Office Exp | D53: office chairs | E53: 1275371000001575110 | I53: journal | K53: 419 | L53: 12000 | N53: 12000 | O53: -1 | P53: 1275371000000169121 | S53: INR | T53: expense | U53: other_expense | V53: Head Office
B54: 45716 | C54: Office Exp | D54: Bajarang Security | E54: 1275371000001663790 | I54: bill | K54: Feb | L54: 27000 | N54: 27000 | O54: 1275371000001663774 | P54: 1275371000000169121 | S54: INR | T54: expense | U54: other_expense | V54: Head Office | W54: Received
B55: 45566 | C55: Office Supplies | D55: Mamta Fresh Mart | E55: 1275371000001374299 | I55: bill | K55: Mamta#07 | L55: 22657 | N55: 22657 | O55: 1275371000000569452 | P55: 1275371000000000498 | S55: INR | T55: expense | U55: expense | V55: Head Office | W55: Received
B56: 45688 | C56: Office Supplies | D56: Mamta Fresh Mart | E56: 1275371000001539291 | I56: bill | K56: #Jan | L56: 23662 | N56: 23662 | O56: 1275371000000569452 | P56: 1275371000000000498 | S56: INR | T56: expense | U56: expense | V56: Head Office | W56: Received
B59: 6. Communication cost
...

Sheet Payroll
B2: ='Requirement list'!B2 -> ETHDC Technologies Pvt. Ltd
B3: ='Requirement list'!B3 -> Statutory Audit for the year ended March 31, 2026
B4: ='Requirement list'!B4 -> Preliminary Requirement list
B6: Employee appointment and FNF letters - Samples
B9: 1. Appointment letters of below :
B11: Employee name
B12: PRATHAMESH GHODKE
B13: AKSHAY KOHALE
B14: SHREYAS SHRIKANT JOSHI
B15: PRATHMESH LOHAR
B18: 2. FNF letters of below employees:
B20: Employee Name
B21: ANITA ABHIJIT THORAT
B22: SATISH JOHARE
B23: ADITI RAIBAGKAR
B24: TUSHAR MAWAL
